Workbook

Sheet Game_Log
A1: Game_ID | B1: Game_Date | C1: Game_Type | D1: Focal_Team | E1: Away_Team | F1: Home_Team | G1: Innings_Played | H1: Source_File | I1: Away_R | J1: Away_H | K1: Away_E | L1: Home_R | M1: Home_H | N1: Home_E | O1: QA_Flag_Count | P1: Notes
A2: 2026-03-10_RVRH_at_WSTF | B2: 46091 | C2: Scrimmage | D2: RVRH | E2: RVRH | F2: WSTF | G2: 8 | H2: Game_01.md | I2: 7 | J2: 10 | K2: 1 | L2: 8 | M2: 9 | N2: 0 | O2: 10 | P2: Walk-off loss, 8 innings. 10 data integrity flags in source log. Courtesy runners used for R Walsh, J Norwood (×2), G Dang. J Norwood also pitched B3 (entry not explicitly logged).
A3: 2026-03-14_WTTN_at_RVRH | B3: 46095 | C3: Scrimmage | D3: RVRH | E3: WTTN | F3: RVRH | G3: 8 | H3: Game_02.md | I3: 4 | J3: 7 | K3: 2 | L3: 7 | M3: 8 | N3: 3 | O3: 12 | P3: RVRH win 7-4, home scrimmage vs. Wootton. 7 innings fully documented; T8 incomplete (Flag #1, J Allen at bat only). Courtesy runner E Skolkin in for C Reis (B7 play #67) — run credited to C Reis. CR J Jenkins in for H Zhang (B5 play #48, inning-ending play, no run scored). L Avila (WTTN) bats T1 then pitches B1-B3 (Flag #11). J Norwood pitches T5 (Flag #10). K_S/K_L discrepancy: A Grainger play #4 Section 3 says 'looking' but Section 4 final pitch 'swinging' — K_S recorded per Section 4. WTTN fielder identities not in log for 2 errors (play #45 1B, play #46 SS). 12 data integrity flags in source log.
A4: 2026-03-21_RVRH_at_GLFR | B4: 46102 | C4: In-Season Game | D4: RVRH | E4: RVRH | F4: GLFR | G4: 6 | H4: Game_03.md | I4: 19 | J4: 12 | K4: 0 | L4: 6 | M4: 5 | N4: 3 | O4: 13 | P4: RVRH win 19-6, away vs. Guilford Park. 5 innings fully documented; T6 incomplete (Flag #1). Game type not labeled in log (Flag #2). GLFR players logged as abbreviated names only, no jersey numbers (Flag #3). Courtesy runners: B Bixby for G Dang (T1, play #7 Sec4; run credited to G Dang); E Skolkin for R Walsh (T1, play #11 Sec4; run credited to R Walsh); R Miller for C Reis (T4, play #44 Sec4; run credited to C Reis); Z M for L R (B5, play #63 Sec4; Z M caught stealing home, CS credited to L R). J Norwood pitches B4–B5 (Flag #7, entry inferred). A A pitches T2–T4 (T4 inferred). 3 RVRH runs scored on errors (plays #14, #15) — no RBI credited. 13 data integrity flags in source log.
A5: 2026-03-23_WLDL_at_RVRH | B5: 46104 | C5: In-Season Game | D5: RVRH | E5: WLDL | F5: RVRH | G5: 5 | H5: Game_04.md | I5: 0 | J5: 3 | K5: 3 | L5: 23 | M5: 18 | N5: 0 | O5: 8 | P5: RVRH win, home vs. Wilde Lake. Game type not labeled (Flag #2-adjacent). FLAG #2: Section 2 reports RVRH R=23; line score and play-by-play both sum to 22 (B2=2, B3=12, B4=8, B5 incomplete with 0 logged). Discrepancy unresolvable — R=23 recorded as reported; batting R tally = 22. G2 gate fails by 1 run (documented, unresolvable). B5 incomplete (Flag #1, B Mougey at bat, no outcome). Courtesy runner B Bixby for G Dang ×2 in B3 (plays #28 and #37 Sec4; Flag #7). Sub note 'CR R Miller in for C Reis' at T4 (play #44) mislabeled — treated as defensive sub; R Miller takes C Reis batting slot in B4. Duplicate lineup note for J Jenkins at play #20 (Flag #3). 8 data integrity flags in source log.
A6: 2026-03-25_RVRH_at_HMMN | B6: 46106 | C6: In-Season Game | D6: RVRH | E6: RVRH | F6: HMMN | G6: 8 | H6: Game_05.md | I6: 13 | J6: 15 | K6: 1 | L6: 2 | M6: 6 | N6: 4 | O6: 10 | P6: RVRH win 13-2, away vs. Hammond. 7 innings fully documented; T8 incomplete (Flag #1, R Walsh at bat only). Game type not labeled. CRs: C McClellan for H Zhang ×3 (T3 #22, T4 #34, T5 #47; Flag #8) — T3 run credited to H Zhang; E Skolkin for G Dang T4 (#36 Sec4) — stranded; D Bhatt for L Tordella B2 (#17 Sec4) — stranded. R Ronayne subs for G Dang in T7 — no lineup note (inferred from batting order). T Thomas appears B7 with no lineup note (Flag #3). P Yarnell (HMMN SS) commits 3 errors (T4 embedded, T5, T7 embedded; Flag #7). 10 data integrity flags in source log.
A7: 2026-03-27_GLNL_at_RVRH | B7: 46108 | C7: In-Season Game | D7: RVRH | E7: GLNL | F7: RVRH | G7: 5 | H7: Game_06.md | I7: 0 | J7: 1 | K7: 1 | L7: 19 | M7: 11 | N7: 2 | O7: 14 | P7: RVRH win 19-0, home vs. Glenelg. 5 complete innings (GLNL doesn't bat B5 per line score; R Miller B5 at-bat in log is inconsistency per Flag #1). Game type not labeled. FLAG #5: RVRH E=2 reported; only 1 error identifiable (C Nichols SS T1 play #3); second RVRH error unresolvable from log — E=2 recorded as reported, 1 fielding row written. B3 is 15-run inning with order cycling twice (Flag #6 C Naecker, Flag #7 G Dang). CRs: B Bixby for G Dang B2 (stranded); B Bixby for G Dang B3 2nd time (scores play #38 → R to G Dang); C McClellan for R Walsh B3 (scores play #34 → R to R Walsh); R Miller 'pinch runner' for C Reis B4 (Flag #4; scores play #48 → R to C Reis). Flag #2: circular pitcher substitution during G Dang SAC fly AB (B3 play #27) — N Cohen credited as active pitcher per final entry in sequence. 14 data integrity flags in source log.
A8: 2026-03-30_FLLS_at_RVRH | B8: 46111 | C8: In-Season Game | D8: RVRH | E8: FLLS | F8: RVRH | G8: 7 | H8: Game_07.md | I8: 3 | J8: 7 | K8: 0 | L8: 7 | M8: 11 | N8: 2 | O8: 9 | P8: RVRH win 7-3, home vs. Fallston. 7 complete top-half innings; B7 in log but line score shows X (RVRH did not bat in B7, Flag #1 — same contradiction as Game 06). Game type not labeled. H Zhang HR T1 (B1 play #8) is a 2-run HR (J Norwood scores). CRs: C McClellan for G Dang B1 (stranded); B Bixby 'pinch runner' for H Zhang B5 (Flag #2, stranded); H Zhang bats again in B6 despite B Bixby pinch-runner sub (Flag #6); Flag #5: 'Play Edit' in C Naecker PO AB B6 (B Bixby/H Zhang swap reversed, net effect H Zhang stays). FLLS CRs: R Cullison for J Potler T2 (stranded); C Blair for J Potler T4 (out on FC). Z Loewe SB×3 (T3 ×2 embedded, T5 ×1 embedded; Flags #7/#9). J Schilpp SB×1 + WP advance T4 embedded (Flag #8). 9 data integrity flags in source log.
A9: 2026-03-07_ELNR_at_NRTH | B9: 46088 | C9: In-Season Game | D9: NRTH | E9: ELNR | F9: NRTH | G9: 5 | H9: Northpoint_Game_8.md | I9: 1 | J9: 1 | K9: 8 | L9: 14 | M9: 10 | N9: 3 | O9: 13 | P9: ELNR loss 1-14, away vs. North Point (mercy rule, 5 innings). 13 data integrity flags. T6 incomplete — scoring artifact (Flag #1). T White identity conflict (Flag #2). CR T Roy for A Williams in B1 (play #15) and B3 (play #35) — T Roy runs credited to A Williams per CR rule (Flag #12). C Pettko (NRTH) pitches T1-T2 and bats — entry inferred from play descriptions (Flag #11). Balk by A Harding T3 (Flag #7). Multiple embedded baserunning events (Flag #13).
A10: 2026-03-14_NRTH_at_ARND | B10: 46095 | C10: In-Season Game | D10: NRTH | E10: NRTH | F10: ARND | G10: 5 | H10: Northpoint_Game_9.md | I10: 1 | J10: 2 | K10: 7 | L10: 21 | M10: 9 | N10: 0 | O10: 10 | P10: NRTH loss 1-21, 5 innings (mercy/run-rule). 10 data integrity flags. NRTH 7 errors (A Harding SS x3, A Williams C x1, W Kwisnek 1B x1, Z Bowman 3B x1, A Thomas 2B x1). Courtesy runner J Perry for G O'Donnell (B2 play#23); R credited to G O'Donnell (play#26 WP). Multiple pitcher changes in B2 anomalous (Flag#4). 1 unattributed run play#63 (score 19->21, only J Haslup credited on WP). B5 incomplete — C Dennehy AB play#64 not counted (Flag#1).
A11: 2026-03-14_NRTH_at_MRRT | B11: 46095 | C11: In-Season Game | D11: NRTH | E11: NRTH | F11: MRRT | G11: 6 | H11: Northpoint_Game_10.md | I11: 2 | J11: 4 | K11: 7 | L11: 15 | M11: 10 | N11: 0 | O11: 14 | P11: NRTH loss 2-15, 6 innings (mercy/run-rule). 14 data integrity flags. NRTH 7 errors (A Thomas 2B x1, A Williams C x2, Z Bowman 3B x2, S Dixon LF x1, Z Bowman P x1). Same-day doubleheader with Game 9 (Flag#2). MRRT unnamed players #2 and #6 (Flag#13). Multiple dual-role players: A Espejo pitches B1-B2, E Zimmerman pitches B3-B4, Z Bowman pitches B5 (Flags#3-5). B6 incomplete - T Rauscher AB play#64 no outcome (Flag#1). CR: R Marsili for S Thomas B2; A Montgomery for T Rauscher B5; runs credited to originals per CR rule.
A12: 2026-03-20_PTXN_at_NRTH | B12: 46101 | C12: In-Season Game | D12: NRTH | E12: PTXN | F12: NRTH | G12: 7 | H12: Northpoint_Game_11.md | I12: 7 | J12: 6 | K12: 4 | L12: 4 | M12: 5 | N12: 2 | O12: 11 | P12: NRTH loss 4-7, 7 complete innings. 11 data integrity flags. NRTH 2 errors: A Harding SS play#16(T2), A Williams C play#50(T6). PTXN 4 errors: R Whitney SS plays#9(B1),#46(B5); D Bradley 3B play#19(B2); N Kelly LF play#57(B6). Dual-role PTXN: C White bats T-halves + pitches B1-B5; R Whitney bats T-halves + pitches B6-B7 (no lineup notes, Flag#10). NRTH dual-role: A Espejo bats B-halves + pitches T1-T5; C Pettko bats B-halves + pitches T6-T7. CR: J Smith for E Zimmerman B6 play#55 (R credited to E Zimmerman per CR rule). CR: R Hawkins for L Powell T6 play#54 (L Powell stranded). T8 play#68 D Bradley no outcome recorded (Flag#1).
A13: 2026-03-23_NRTH_at_ST.C | B13: 46104 | C13: In-Season Game | D13: NRTH | E13: NRTH | F13: ST.C | G13: 7 | H13: Northpoint_Game_12.md | I13: 7 | J13: 5 | K13: 0 | L13: 0 | M13: 1 | N13: 1 | O13: 12 | P13: NRTH win 7-0, 7 complete innings. First NRTH win in series (Flag#2). 12 data integrity flags. NRTH 0 errors. ST.C 1 error: R Generette 1B play#4(T1). E Zimmerman pitches all 7 B-halves (no lineup note, established via attribution). Balk by E Zimmerman B6 play#46 (D Tyler adv 2nd, not in schema). Inside-the-park HR A Harding T3 play#19 (Flag#4). CR C Harrigan for E Zimmerman T6 play#41 (R credited to E Zimmerman per CR rule). T8 play#56 E Zimmerman AB no outcome recorded (Flag#1). S Dixon steals 2nd while at 3rd (anomalous, recorded as logged, Flag#10). Two WPs by M Minick T6 (plays#41,#42) score A Harding and Z Bowman.
... A47: 2026-03-31_CNTN_at_WLTR | B47: 46112 | C47: In-Season Game | D47: CNTN | E47: CNTN | F47: WLTR | G47: 7 | H47: Centennial_Game_6.md | I47: 3 | J47: 5 | K47: 5 | L47: 3 | M47: 6 | N47: 4 | O47: 7 | P47: 3-3 tie — game called during Top 8th (time limit, Flag #7; 7 complete inn). CNTN scoring: 3R T2 (E Ogg/B Harris scores D Hill 1B; B Corrao scores A Gauthier walk; D Hill scores E Rayne walk). WLTR scoring: 1R B1 (C Martin/S Weston CR scores on C Stachera WP); 1R B3 (S Weston scores on C Stachera error CNTN E#3, embedded in G Matalia D3S AB); 1R B6 (H Bauer scores J Gilder SacFly). CR E Ogg for B Harris ×3 (plays #11,#26,#62); CR C Proescher for C Stachera (play #27 T3). CR C Martin for S Weston B1 play #7 — C Martin SB play #7 credited to S Weston; C Martin/S Weston run play #9 credited to S Weston. J Pena Simon caught stealing home B7 play #66 (Flag #2). Phantom T8 entry (play #68) — C Stachera at bat, no outcome, game called (Flag #7). RBI advisory: WLTR 3R, 1 RBI — 2 unaccounted (WP play #9, error play #31). CNTN 3R, 3 RBI — all accounted.

Sheet Batting
A1: Game_ID | B1: Game_Date | C1: Opponent | D1: Team | E1: Player | F1: PA | G1: AB | H1: H | I1: 1B | J1: 2B | K1: 3B | L1: HR | M1: BB | N1: HBP | O1: K | P1: K_L | Q1: K_S | R1: R | S1: RBI | T1: SB | U1: CS | V1: GDP | W1: SAC | X1: FC | Y1: Notes
A2: 2026-03-10_RVRH_at_WSTF | B2: 46091 | C2: Westfield High School | D2: RVRH | E2: R Walsh | F2: 4 | G2: 3 | H2: 2 | I2: 1 | J2: 1 | K2: 0 | L2: 0 | M2: 1 | N2: 0 | O2: 0 | P2: 0 | Q2: 0 | R2: 2 | S2: 2 | T2: 0 | U2: 0 | V2: 0 | W2: 0 | X2: 0 | Y2: R in T1 via CR B Bixby (play #3); 2 RBI on T4 single (play #33); replaced by L Kreisl PH in T8
A3: 2026-03-10_RVRH_at_WSTF | B3: 46091 | C3: Westfield High School | D3: RVRH | E3: C Reis | F3: 4 | G3: 4 | H3: 2 | I3: 2 | J3: 0 | K3: 0 | L3: 0 | M3: 0 | N3: 0 | O3: 0 | P3: 0 | Q3: 0 | R3: 1 | S3: 2 | T3: 0 | U3: 0 | V3: 0 | W3: 0 | X3: 0 | Y3: Scores T1 play #4 (H Zhang singles); 2 RBI on T4 single (play #34); also pitches B7
A4: 2026-03-10_RVRH_at_WSTF | B4: 46091 | C4: Westfield High School | D4: RVRH | E4: J Norwood | F4: 4 | G4: 4 | H4: 3 | I4: 2 | J4: 1 | K4: 0 | L4: 0 | M4: 0 | N4: 0 | O4: 0 | P4: 0 | Q4: 0 | R4: 1 | S4: 1 | T4: 0 | U4: 0 | V4: 0 | W4: 0 | X4: 1 | Y4: FC play #35; sub inconsistency plays #58/#59 (Flag #1); CR B Bixby used T3+T7; also pitches B3 (inferred)
A5: 2026-03-10_RVRH_at_WSTF | B5: 46091 | C5: Westfield High School | D5: RVRH | E5: H Zhang | F5: 3 | G5: 2 | H5: 1 | I5: 1 | J5: 0 | K5: 0 | L5: 0 | M5: 1 | N5: 0 | O5: 1 | P5: 0 | Q5: 1 | R5: 0 | S5: 1 | T5: 0 | U5: 0 | V5: 0 | W5: 0 | X5: 0 | Y5: RBI on T1 single (play #4); K_S in T5
A6: 2026-03-10_RVRH_at_WSTF | B6: 46091 | C6: Westfield High School | D6: RVRH | E6: C Naecker | F6: 3 | G6: 2 | H6: 0 | I6: 0 | J6: 0 | K6: 0 | L6: 0 | M6: 1 | N6: 0 | O6: 1 | P6: 0 | Q6: 1 | R6: 0 | S6: 1 | T6: 1 | U6: 0 | V6: 0 | W6: 0 | X6: 0 | Y6: RBI via productive GO T1 (play #5); SB embedded in play #43 pitch seq; replaced by R Ronayne PH T7
A7: 2026-03-10_RVRH_at_WSTF | B7: 46091 | C7: Westfield High School | D7: RVRH | E7: G Dang | F7: 3 | G7: 3 | H7: 1 | I7: 1 | J7: 0 | K7: 0 | L7: 0 | M7: 0 | N7: 0 | O7: 0 | P7: 0 | Q7: 0 | R7: 1 | S7: 0 | T7: 0 | U7: 0 | V7: 0 | W7: 0 | X7: 1 | Y7: R via CR E Skolkin scoring play #33; CR used from T4 onward; FC play #6
A8: 2026-03-10_RVRH_at_WSTF | B8: 46091 | C8: Westfield High School | D8: RVRH | E8: A Fields | F8: 4 | G8: 2 | H8: 0 | I8: 0 | J8: 0 | K8: 0 | L8: 0 | M8: 2 | N8: 0 | O8: 1 | P8: 1 | Q8: 0 | R8: 1 | S8: 0 | T8: 0 | U8: 0 | V8: 0 | W8: 0 | X8: 0 | Y8: K_L play #44; scores on throw play #33; 2 BB; also plays 2B
A9: 2026-03-10_RVRH_at_WSTF | B9: 46091 | C9: Westfield High School | D9: RVRH | E9: E McCoy | F9: 4 | G9: 3 | H9: 1 | I9: 1 | J9: 0 | K9: 0 | L9: 0 | M9: 1 | N9: 0 | O9: 2 | P9: 0 | Q9: 2 | R9: 1 | S9: 0 | T9: 0 | U9: 1 | V9: 0 | W9: 0 | X9: 0 | Y9: K play #62 was dropped 3rd strike (out at 1B); CS embedded in play #52 pitch seq; also plays CF
A10: 2026-03-10_RVRH_at_WSTF | B10: 46091 | C10: Westfield High School | D10: RVRH | E10: C Nichols | F10: 3 | G10: 3 | H10: 0 | I10: 0 | J10: 0 | K10: 0 | L10: 0 | M10: 0 | N10: 0 | O10: 3 | P10: 1 | Q10: 2 | R10: 0 | S10: 0 | T10: 0 | U10: 0 | V10: 0 | W10: 0 | X10: 0 | Y10: K_L play #66; K_S plays #14 and #31; also pitches B8
A11: 2026-03-10_RVRH_at_WSTF | B11: 46091 | C11: Westfield High School | D11: RVRH | E11: A Contreras | F11: 3 | G11: 3 | H11: 0 | I11: 0 | J11: 0 | K11: 0 | L11: 0 | M11: 0 | N11: 0 | O11: 1 | P11: 0 | Q11: 1 | R11: 0 | S11: 0 | T11: 0 | U11: 0 | V11: 0 | W11: 0 | X11: 0 | Y11: Replaced by B Mougey PH in T8
A12: 2026-03-10_RVRH_at_WSTF | B12: 46091 | C12: Westfield High School | D12: RVRH | E12: B Bixby | F12: 1 | G12: 1 | H12: 0 | I12: 0 | J12: 0 | K12: 0 | L12: 0 | M12: 0 | N12: 0 | O12: 0 | P12: 0 | Q12: 0 | R12: 0 | S12: 0 | T12: 0 | U12: 0 | V12: 0 | W12: 0 | X12: 0 | Y12: Bats T7 play #58; CR for R Walsh (T1) and J Norwood (T3); sub inconsistency see Flag #1
A13: 2026-03-10_RVRH_at_WSTF | B13: 46091 | C13: Westfield High School | D13: RVRH | E13: R Ronayne | F13: 1 | G13: 1 | H13: 0 | I13: 0 | J13: 0 | K13: 0 | L13: 0 | M13: 0 | N13: 0 | O13: 1 | P13: 0 | Q13: 1 | R13: 0 | S13: 0 | T13: 0 | U13: 0 | V13: 0 | W13: 0 | X13: 0 | Y13: PH for C Naecker T7 (play #60); also pitches B5-B6
... A161: 2026-03-07_ELNR_at_NRTH | B161: 46088 | C161: North Point Varsity Eagles | D161: ELNR | E161: B Durham | F161: 3 | G161: 2 | H161: 1 | I161: 1 | J161: 0 | K161: 0 | L161: 0 | M161: 0 | N161: 1 | O161: 1 | P161: 0 | Q161: 1 | R161: 0 | S161: 0 | T161: 1 | U161: 0 | V161: 0 | W161: 0 | X161: 0 | Y161: SB T1 (Seq#3 embedded during C Knight walk); K_S T4 (Seq#43).
A162: 2026-03-07_ELNR_at_NRTH | B162: 46088 | C162: North Point Varsity Eagles | D162: ELNR | E162: S Hamilton | F162: 3 | G162: 3 | H162: 0 | I162: 0 | J162: 0 | K162: 0 | L162: 0 | M162: 0 | N162: 0 | O162: 0 | P162: 0 | Q162: 0 | R162: 0 | S162: 0 | T162: 0 | U162: 0 | V162: 0 | W162: 0 | X162: 0
A163: 2026-03-07_ELNR_at_NRTH | B163: 46088 | C163: North Point Varsity Eagles | D163: ELNR | E163: C Knight | F163: 3 | G163: 0 | H163: 0 | I163: 0 | J163: 0 | K163: 0 | L163: 0 | M163: 3 | N163: 0 | O163: 0 | P163: 0 | Q163: 0 | R163: 1 | S163: 0 | T163: 0 | U163: 0 | V163: 0 | W163: 0 | X163: 0 | Y163: R scored on balk by A Harding, T3 (play #33); see Flag #7. Pickoff at 1st (play #52) embedded in J Maitland AB — not a PA; see Flag #10.
A164: 2026-03-07_ELNR_at_NRTH | B164: 46088 | C164: North Point Varsity Eagles | D164: ELNR | E164: J Maitland | F164: 4 | G164: 4 | H164: 0 | I164: 0 | J164: 0 | K164: 0 | L164: 0 | M164: 0 | N164: 0 | O164: 3 | P164: 1 | Q164: 2 | R164: 0 | S164: 0 | T164: 1 | U164: 0 | V164: 0 | W164: 0 | X164: 0 | Y164: K_S T1 (Seq#4), K_S T3 (Seq#30), K_L T4 (Seq#41). SB T5 (Seq#53). Catcher errors ELNR E=2 (play #12), E=3 (play #15), E=6 (play #36) attributed to J Maitland in Fielding.
A165: 2026-03-07_ELNR_at_NRTH | B165: 46088 | C165: North Point Varsity Eagles | D165: ELNR | E165: R Coxen | F165: 3 | G165: 2 | H165: 0 | I165: 0 | J165: 0 | K165: 0 | L165: 0 | M165: 1 | N165: 0 | O165: 0 | P165: 0 | Q165: 0 | R165: 0 | S165: 0 | T165: 0 | U165: 0 | V165: 0 | W165: 0 | X165: 0
A166: 2026-03-07_ELNR_at_NRTH | B166: 46088 | C166: North Point Varsity Eagles | D166: ELNR | E166: K Watkins-Fleisher | F166: 2 | G166: 2 | H166: 0 | I166: 0 | J166: 0 | K166: 0 | L166: 0 | M166: 0 | N166: 0 | O166: 0 | P166: 0 | Q166: 0 | R166: 0 | S166: 0 | T166: 0 | U166: 0 | V166: 0 | W166: 0 | X166: 0
A167: 2026-03-07_ELNR_at_NRTH | B167: 46088 | C167: North Point Varsity Eagles | D167: ELNR | E167: A Kennell | F167: 2 | G167: 2 | H167: 0 | I167: 0 | J167: 0 | K167: 0 | L167: 0 | M167: 0 | N167: 0 | O167: 1 | P167: 0 | Q167: 1 | R167: 0 | S167: 0 | T167: 0 | U167: 0 | V167: 0 | W167: 0 | X167: 0 | Y167: K_S T3 (Seq#33; balk embedded in AB — see Flag #7). Also pitches B5 (entry inferred).
A168: 2026-03-07_ELNR_at_NRTH | B168: 46088 | C168: North Point Varsity Eagles | D168: ELNR | E168: J Burke | F168: 2 | G168: 2 | H168: 0 | I168: 0 | J168: 0 | K168: 0 | L168: 0 | M168: 0 | N168: 0 | O168: 1 | P168: 1 | Q168: 0 | R168: 0 | S168: 0 | T168: 0 | U168: 0 | V168: 1 | W168: 0 | X168: 0 | Y168: GDP T2 (play #20). K_L T4 (Seq#41). Also pitches B1.
A169: 2026-03-07_ELNR_at_NRTH | B169: 46088 | C169: North Point Varsity Eagles | D169: ELNR | E169: A Wimbish | F169: 2 | G169: 1 | H169: 0 | I169: 0 | J169: 0 | K169: 0 | L169: 0 | M169: 0 | N169: 1 | O169: 0 | P169: 0 | Q169: 0 | R169: 0 | S169: 0 | T169: 0 | U169: 0 | V169: 0 | W169: 0 | X169: 0 | Y169: HBP T2 (play #21).
A170: 2026-03-07_ELNR_at_NRTH | B170: 46088 | C170: North Point Varsity Eagles | D170: ELNR | E170: T White | F170: 0 | G170: 0 | H170: 0 | I170: 0 | J170: 0 | K170: 0 | L170: 0 | M170: 0 | N170: 0 | O170: 0 | P170: 0 | Q170: 0 | R170: 0 | S170: 0 | T170: 0 | U170: 0 | V170: 0 | W170: 0 | X170: 0 | Y170: T6 AB — no outcome recorded; scoring artifact per Flag #1. Identity conflict with NRTH fielder T White; see Flag #2.
A171: 2026-03-07_ELNR_at_NRTH | B171: 46088 | C171: North Point Varsity Eagles | D171: NRTH | E171: A Espejo | F171: 4 | G171: 1 | H171: 1 | I171: 1 | J171: 0 | K171: 0 | L171: 0 | M171: 3 | N171: 0 | O171: 0 | P171: 0 | Q171: 0 | R171: 2 | S171: 0 | T171: 1 | U171: 0 | V171: 0 | W171: 0 | X171: 0 | Y171: SB B3 (Seq#37, embedded during A Thomas AB). R: B1 via Z Bowman single (play #10); B3 via A Harding sac fly (play #38).
A172: 2026-03-07_ELNR_at_NRTH | B172: 46088 | C172: North Point Varsity Eagles | D172: NRTH | E172: A Thomas | F172: 4 | G172: 4 | H172: 2 | I172: 2 | J172: 0 | K172: 0 | L172: 0 | M172: 0 | N172: 0 | O172: 0 | P172: 0 | Q172: 0 | R172: 0 | S172: 3 | T172: 0 | U172: 0 | V172: 0 | W172: 0 | X172: 1 | Y172: RBI x3: C Pettko (play #17 B1), T Roy/A Williams credited (play #17 B1), C Pettko (play #37 B3).
A173: 2026-03-07_ELNR_at_NRTH | B173: 46088 | C173: North Point Varsity Eagles | D173: NRTH | E173: A Harding | F173: 3 | G173: 2 | H173: 0 | I173: 0 | J173: 0 | K173: 0 | L173: 0 | M173: 0 | N173: 0 | O173: 0 | P173: 0 | Q173: 0 | R173: 1 | S173: 1 | T173: 0 | U173: 0 | V173: 0 | W173: 1 | X173: 0 | Y173: R B1 (play #12 on W Kwisnek single; advances 3rd on throw, scores on catcher error — no RBI). RBI on sac fly B3 (play #38, A Espejo scores). Also pitches T3 (entry inferred).
A174: 2026-03-07_ELNR_at_NRTH | B174: 46088 | C174: North Point Varsity Eagles | D174: NRTH | E174: Z Bowman | F174: 3 | G174: 3 | H174: 1 | I174: 1 | J174: 0 | K174: 0 | L174: 0 | M174: 0 | N174: 0 | O174: 0 | P174: 0 | Q174: 0 | R174: 3 | S174: 1 | T174: 0 | U174: 0 | V174: 0 | W174: 0 | X174: 1 | Y174: RBI on 1B B1 (play #10, A Espejo scores). R x3: B1 via W Kwisnek single; B2 via S Dixon error; B3 via E Zimmerman single. Also pitches T4 (inferred).
A175: 2026-03-07_ELNR_at_NRTH | B175: 46088 | C175: North Point Varsity Eagles | D175: NRTH | E175: E Zimmerman | F175: 4 | G175: 4 | H175: 1 | I175: 1 | J175: 0 | K175: 0 | L175: 0 | M175: 0 | N175: 0 | O175: 1 | P175: 0 | Q175: 1 | R175: 0 | S175: 1 | T175: 0 | U175: 0 | V175: 0 | W175: 0 | X175: 0 | Y175: K_S B1 (Seq#11). 1B B3 (play #40) with batter-runner out advancing to 2nd; see Flag #9.
A176: 2026-03-07_ELNR_at_NRTH | B176: 46088 | C176: North Point Varsity Eagles | D176: NRTH | E176: W Kwisnek | F176: 4 | G176: 4 | H176: 2 | I176: 1 | J176: 0 | K176: 0 | L176: 1 | M176: 0 | N176: 0 | O176: 0 | P176: 0 | Q176: 0 | R176: 2 | S176: 2 | T176: 0 | U176: 0 | V176: 0 | W176: 0 | X176: 0 | Y176: 1B B1 (play #12): Z Bowman scores (RBI); A Harding scores on subsequent catcher error — no RBI for that run. Solo HR B4 (play #44, RBI). R: B1 via S Dixon single; B4 own HR.
A177: 2026-03-07_ELNR_at_NRTH | B177: 46088 | C177: North Point Varsity Eagles | D177: NRTH | E177: S Dixon | F177: 5 | G177: 4 | H177: 1 | I177: 1 | J177: 0 | K177: 0 | L177: 0 | M177: 1 | N177: 0 | O177: 0 | P177: 0 | Q177: 0 | R177: 1 | S177: 1 | T177: 2 | U177: 1 | V177: 0 | W177: 0 | X177: 0 | Y177: SB x2: 2nd (Seq#14 B1), 3rd (Seq#15 B1). CS B2 (play #28, Seq#28). R scored B1 on error during C Pettko walk (play #15) — no RBI. Advances to 2nd on WP before CS attempt; see Flag #6.
A178: 2026-03-07_ELNR_at_NRTH | B178: 46088 | C178: North Point Varsity Eagles | D178: NRTH | E178: A Williams | F178: 4 | G178: 1 | H178: 1 | I178: 0 | J178: 1 | K178: 0 | L178: 0 | M178: 2 | N178: 1 | O178: 0 | P178: 0 | Q178: 0 | R178: 2 | S178: 0 | T178: 0 | U178: 0 | V178: 0 | W178: 0 | X178: 0 | Y178: R x2 credited from CR T Roy per Flag #12: T Roy scores B1 (play #17); T Roy scores B3 (play #36 error). 2B B4 (play #46). HBP B3 (play #34).
... A314: 2026-03-26_THMS_at_NRTH | B314: 46107 | C314: NRTH | D314: THMS | E314: #22 | F314: 1 | G314: 1 | H314: 0 | I314: 0 | J314: 0 | K314: 0 | L314: 0 | M314: 0 | N314: 0 | O314: 1 | P314: 1 | Q314: 0 | R314: 0 | S314: 0 | T314: 0 | U314: 0 | V314: 0 | W314: 0 | X314: 0 | Y314: K_L T4 Seq#52; enters T4 with no lineup note (Flag#15); credited with pickoff of T Roy at 1B in B3 Seq#48
A315: 2026-03-07_DMSC_at_GLNL | B315: 46088 | C315: GLNL | D315: DMSC | E315: J Reyes | F315: 4 | G315: 3 | H315: 0 | I315: 0 | J315: 0 | K315: 0 | L315: 0 | M315: 1 | N315: 0 | O315: 1 | P315: 0 | Q315: 1 | R315: 0 | S315: 0 | T315: 0 | U315: 0 | V315: 0 | W315: 0 | X315: 0
A316: 2026-03-07_DMSC_at_GLNL | B316: 46088 | C316: GLNL | D316: DMSC | E316: K Childers | F316: 4 | G316: 3 | H316: 2 | I316: 2 | J316: 0 | K316: 0 | L316: 0 | M316: 1 | N316: 0 | O316: 0 | P316: 0 | Q316: 0 | R316: 1 | S316: 0 | T316: 0 | U316: 0 | V316: 0 | W316: 0 | X316: 0
A317: 2026-03-07_DMSC_at_GLNL | B317: 46088 | C317: GLNL | D317: DMSC | E317: A Iorio | F317: 4 | G317: 3 | H317: 1 | I317: 1 | J317: 0 | K317: 0 | L317: 0 | M317: 1 | N317: 0 | O317: 1 | P317: 1 | Q317: 0 | R317: 0 | S317: 0 | T317: 0 | U317: 0 | V317: 0 | W317: 0 | X317: 0
A318: 2026-03-07_DMSC_at_GLNL | B318: 46088 | C318: GLNL | D318: DMSC | E318: G Iorio | F318: 4 | G318: 3 | H318: 0 | I318: 0 | J318: 0 | K318: 0 | L318: 0 | M318: 1 | N318: 0 | O318: 3 | P318: 1 | Q318: 2 | R318: 0 | S318: 0 | T318: 0 | U318: 0 | V318: 0 | W318: 0 | X318: 0
A319: 2026-03-07_DMSC_at_GLNL | B319: 46088 | C319: GLNL | D319: DMSC | E319: L Curtin | F319: 4 | G319: 4 | H319: 1 | I319: 1 | J319: 0 | K319: 0 | L319: 0 | M319: 0 | N319: 0 | O319: 2 | P319: 2 | Q319: 0 | R319: 1 | S319: 1 | T319: 0 | U319: 0 | V319: 0 | W319: 0 | X319: 0 | Y319: Scored T2 on C Holland SAC fly; RBI T5 on single (K Childers scores)
A320: 2026-03-07_DMSC_at_GLNL | B320: 46088 | C320: GLNL | D320: DMSC | E320: C Gardner | F320: 4 | G320: 4 | H320: 2 | I320: 2 | J320: 0 | K320: 0 | L320: 0 | M320: 0 | N320: 0 | O320: 0 | P320: 0 | Q320: 0 | R320: 0 | S320: 0 | T320: 1 | U320: 0 | V320: 1 | W320: 0 | X320: 1 | Y320: SB play#34 (embedded in R Chidakel AB, T4); GDP play#50 (DP with L Curtin); FC play#14
A321: 2026-03-07_DMSC_at_GLNL | B321: 46088 | C321: GLNL | D321: DMSC | E321: R Chidakel | F321: 3 | G321: 1 | H321: 1 | I321: 0 | J321: 1 | K321: 0 | L321: 0 | M321: 2 | N321: 0 | O321: 0 | P321: 0 | Q321: 0 | R321: 0 | S321: 0 | T321: 0 | U321: 0 | V321: 0 | W321: 0 | X321: 0
A322: 2026-03-07_DMSC_at_GLNL | B322: 46088 | C322: GLNL | D322: DMSC | E322: C Holland | F322: 3 | G322: 2 | H322: 0 | I322: 0 | J322: 0 | K322: 0 | L322: 0 | M322: 0 | N322: 0 | O322: 2 | P322: 0 | Q322: 2 | R322: 0 | S322: 1 | T322: 0 | U322: 0 | V322: 0 | W322: 1 | X322: 0 | Y322: SAC fly T2 (L Curtin scores, RBI); SAC credited per explicit outcome label
...

Sheet Pitching
A1: Game_ID | B1: Game_Date | C1: Opponent | D1: Team | E1: Pitcher | F1: Outs_Recorded | G1: BF | H1: H_Allowed | I1: 1B_Allowed | J1: 2B_Allowed | K1: 3B_Allowed | L1: HR_Allowed | M1: BB_Allowed | N1: HBP_Allowed | O1: K | P1: R_Allowed | Q1: WP | R1: Notes
A2: 2026-03-10_RVRH_at_WSTF | B2: 46091 | C2: Westfield High School | D2: RVRH | E2: R Walsh | F2: 6 | G2: 9 | H2: 1 | I2: 1 | J2: 0 | K2: 0 | L2: 0 | M2: 2 | N2: 0 | O2: 2 | P2: 0 | Q2: 0 | R2: B1-B2; exit not explicitly logged — inferred from J Norwood pitching B3
A3: 2026-03-10_RVRH_at_WSTF | B3: 46091 | C3: Westfield High School | D3: RVRH | E3: J Norwood | F3: 3 | G3: 3 | H3: 0 | I3: 0 | J3: 0 | K3: 0 | L3: 0 | M3: 0 | N3: 0 | O3: 2 | P3: 0 | Q3: 0 | R3: B3; entry not logged with 'Lineup changed' note; inferred from play descriptions; also bats and plays 1B
A4: 2026-03-10_RVRH_at_WSTF | B4: 46091 | C4: Westfield High School | D4: RVRH | E4: J Jenkins | F4: 3 | G4: 5 | H4: 1 | I4: 1 | J4: 0 | K4: 0 | L4: 0 | M4: 1 | N4: 0 | O4: 0 | P4: 1 | Q4: 1 | R4: B4; 'Lineup changed: J Jenkins in at pitcher' play #36; WP embedded in play #40 pitch sequence
A5: 2026-03-10_RVRH_at_WSTF | B5: 46091 | C5: Westfield High School | D5: RVRH | E5: R Ronayne | F5: 6 | G5: 9 | H5: 2 | I5: 2 | J5: 0 | K5: 0 | L5: 0 | M5: 0 | N5: 1 | O5: 1 | P5: 2 | Q5: 0 | R5: B5-B6; also PH bats T7; HBP to WSTF_#9 play #45
A6: 2026-03-10_RVRH_at_WSTF | B6: 46091 | C6: Westfield High School | D6: RVRH | E6: C Reis | F6: 3 | G6: 3 | H6: 0 | I6: 0 | J6: 0 | K6: 0 | L6: 0 | M6: 1 | N6: 0 | O6: 0 | P6: 0 | Q6: 0 | R6: B7; 'Lineup changed: C Reis in at pitcher' play #63; also bats
A7: 2026-03-10_RVRH_at_WSTF | B7: 46091 | C7: Westfield High School | D7: RVRH | E7: C Nichols | F7: 2 | G7: 9 | H7: 5 | I7: 4 | J7: 0 | K7: 1 | L7: 0 | M7: 1 | N7: 0 | O7: 0 | P7: 5 | Q7: 0 | R7: B8; walk-off loss — game ended with 2 outs; 5 R allowed in final inning; also bats
A8: 2026-03-10_RVRH_at_WSTF | B8: 46091 | C8: Westfield High School | D8: WSTF | E8: WSTF_#1 | F8: 6 | G8: 10 | H8: 4 | I8: 2 | J8: 2 | K8: 0 | L8: 0 | M8: 0 | N8: 0 | O8: 3 | P8: 3 | Q8: 0 | R8: T1-T2; 'Lineup changed: #1 in at pitcher' noted play #1; allowed 3 R in T1
A9: 2026-03-10_RVRH_at_WSTF | B9: 46091 | C9: Westfield High School | D9: WSTF | E9: WSTF_#9 | F9: 6 | G9: 11 | H9: 2 | I9: 2 | J9: 0 | K9: 0 | L9: 0 | M9: 3 | N9: 0 | O9: 4 | P9: 0 | Q9: 0 | R9: T3 + partial T4 (3 BF, 0 outs) + T8; non-consecutive stints combined; entry to T3 not explicitly logged; also bats
A10: 2026-03-10_RVRH_at_WSTF | B10: 46091 | C10: Westfield High School | D10: WSTF | E10: WSTF_#8 | F10: 5 | G10: 8 | H10: 2 | I10: 2 | J10: 0 | K10: 0 | L10: 0 | M10: 1 | N10: 0 | O10: 2 | P10: 4 | Q10: 0 | R10: Partial T4 (play #31 onward, 3 outs) + partial T5 (plays #41-43, 2 outs); entry inferred from '#8 pitching' note play #31; 4 R allowed in T4 on consecutive singles
A11: 2026-03-10_RVRH_at_WSTF | B11: 46091 | C11: Westfield High School | D11: WSTF | E11: WSTF_#3 | F11: 3 | G11: 3 | H11: 1 | I11: 1 | J11: 0 | K11: 0 | L11: 0 | M11: 0 | N11: 0 | O11: 1 | P11: 0 | Q11: 0 | R11: Partial T5 (play #44, 1 out) + partial T6 (plays #51-52, 2 outs incl. E McCoy CS); entry inferred from '#3 pitching' note play #44; also bats
A12: 2026-03-10_RVRH_at_WSTF | B12: 46091 | C12: Westfield High School | D12: WSTF | E12: WSTF_#2 | F12: 4 | G12: 7 | H12: 1 | I12: 1 | J12: 0 | K12: 0 | L12: 0 | M12: 2 | N12: 0 | O12: 2 | P12: 0 | Q12: 0 | R12: Partial T6 (plays #53-54, 1 out) + T7 (plays #58-62, 3 outs); PB embedded in play #61 pitch seq (R Miller advances to 2nd — not in schema); also bats
A13: 2026-03-14_WTTN_at_RVRH | B13: 46095 | C13: Wootton Varsity Patriots | D13: RVRH | E13: H Zhang | F13: 6 | G13: 8 | H13: 2 | I13: 1 | J13: 1 | K13: 0 | L13: 0 | M13: 1 | N13: 0 | O13: 2 | P13: 1 | Q13: 1 | R13: T1-T2; WP during J Arnold AB T1 (play #3, Section 4 — J Reid advances to 2nd); K type discrepancy play #4 (Section 3 'looking' vs Section 4 'swinging' — K_S recorded per Section 4); also bats and plays 1B
... A191: 2026-04-01_OLDM_at_RVRH | B191: 46113 | C191: Old Mill Varsity Patriots | D191: OLDM | E191: B Rzepkoski | F191: 1 | G191: 2 | H191: 0 | I191: 0 | J191: 0 | K191: 0 | L191: 0 | M191: 1 | N191: 0 | O191: 0 | P191: 0 | Q191: 0 | R191: B7 plays #82-83; entry inferred (Flag #6); also bats as OLDM player
A192: 2026-03-31_DMSC_at_HWRD | B192: 46112 | C192: Howard Varsity Lions | D192: DMSC | E192: Thomas Malouf | F192: 15 | G192: 17 | H192: 2 | M192: 0 | N192: 0 | O192: 3 | P192: 0 | Q192: 1 | R192: (W) designation; not written to column. Pitches-Strikes: 49-35. ER=0 = R_Allowed.
A193: 2026-03-31_DMSC_at_HWRD | B193: 46112 | C193: Howard Varsity Lions | D193: DMSC | E193: C Gardner | F193: 3 | G193: 4 | H193: 0 | M193: 1 | N193: 0 | O193: 0 | P193: 0 | Q193: 0 | R193: Name in source: Conor Gardner. Pitches-Strikes: 13-6. ER=0 = R_Allowed.
A194: 2026-03-31_DMSC_at_HWRD | B194: 46112 | C194: Damascus Varsity Hornets | D194: HWRD | E194: A Proescher | F194: 6 | G194: 10 | H194: 3 | M194: 0 | N194: 1 | O194: 4 | P194: 3 | Q194: 1 | R194: (L) designation; not written to column. Name in source: Austin Proescher. ER=2; R_Allowed=3 — 1 unearned run allowed.
A195: 2026-03-31_DMSC_at_HWRD | B195: 46112 | C195: Damascus Varsity Hornets | D195: HWRD | E195: Thomas Estrada | F195: 4 | G195: 8 | H195: 1 | M195: 3 | N195: 0 | O195: 3 | P195: 2 | Q195: 0 | R195: ER=2 = R_Allowed.
A196: 2026-03-31_DMSC_at_HWRD | B196: 46112 | C196: Damascus Varsity Hornets | D196: HWRD | E196: C Hudson | F196: 6 | G196: 14 | H196: 3 | M196: 4 | N196: 0 | O196: 2 | P196: 6 | Q196: 2 | R196: Name in source: Carter Hudson. ER=4 [AMBIGUOUS: team ER total of 8 consistent with ER=3; individual OCR read was 4]; R_Allowed=6 — unearned runs present.
A197: 2026-03-31_DMSC_at_HWRD | B197: 46112 | C197: Damascus Varsity Hornets | D197: HWRD | E197: Gibson Martin | F197: 2 | G197: 5 | H197: 3 | M197: 0 | N197: 0 | O197: 1 | P197: 1 | Q197: 0 | R197: ER=1 = R_Allowed.
A198: 2026-03-21_HWRD_at_HMMN | B198: 46102 | C198: Hammond Varsity Bears | D198: HWRD | E198: B Giangrasso | F198: 16 | G198: 19 | H198: 1 | M198: 0 | N198: 0 | O198: 8 | P198: 2 | Q198: 0 | R198: (W) designation; not written to column. Name in source: Brennan Giangrasso. ER=0; R_Allowed=2 — 2 unearned runs. Pitches-Strikes: 71-47.
A199: 2026-03-21_HWRD_at_HMMN | B199: 46102 | C199: Hammond Varsity Bears | D199: HWRD | E199: N Hegedus | F199: 5 | G199: 6 | H199: 1 | M199: 0 | N199: 0 | O199: 3 | P199: 0 | Q199: 0 | R199: Name in source: Nate Hegedus. ER=0 = R_Allowed. Pitches-Strikes: 26-16.
A200: 2026-03-21_HWRD_at_HMMN | B200: 46102 | C200: Howard Varsity Lions | D200: HMMN | E200: C Stryker | F200: 10 | G200: 16 | H200: 4 | M200: 0 | N200: 0 | O200: 6 | P200: 5 | Q200: 1 | R200: (L) designation; not written to column. Name in source: Collin Stryker. ER=2; R_Allowed=5 — 3 unearned runs. Pitches-Strikes: 65-45.
A201: 2026-03-21_HWRD_at_HMMN | B201: 46102 | C201: Howard Varsity Lions | D201: HMMN | E201: L Duckworth | F201: 5 | G201: 10 | H201: 2 | M201: 0 | N201: 3 | O201: 1 | P201: 2 | Q201: 2 | R201: Name in source: Luke Duckworth. ER=2 = R_Allowed. Pitches-Strikes: 30-17.
A202: 2026-03-21_HWRD_at_HMMN | B202: 46102 | C202: Howard Varsity Lions | D202: HMMN | E202: Darsh Bhatt | F202: 3 | G202: 4 | H202: 0 | M202: 1 | N202: 0 | O202: 1 | P202: 0 | Q202: 0 | R202: ER=0 = R_Allowed. Pitches-Strikes: 16-7.
A203: 2026-03-21_HWRD_at_HMMN | B203: 46102 | C203: Howard Varsity Lions | D203: HMMN | E203: G Garris | F203: 3 | G203: 7 | H203: 1 | M203: 2 | N203: 1 | O203: 2 | P203: 1 | Q203: 0 | R203: Name in source: Griffin Garris. ER=0; R_Allowed=1 — 1 unearned run. Pitches-Strikes: 26-12.
... A246: 2026-04-04_PRKS_at_PLYV | B246: 46116 | C246: Poly Varsity Engineers 2026 | D246: PRKS | E246: James Robbins | F246: 3 | G246: 8 | H246: 2 | M246: 1 | N246: 1 | O246: 2 | P246: 3 | Q246: 1 | R246: Pitches-Strikes: 33-17 (not in schema). ER=3 = R_Allowed. HBP_Allowed=1 (Kingston Antonio or Joshua Tyree). WP=1.
A247: 2026-03-14_CNTN_at_WSTM | B247: 46095 | C247: Westminster Varsity Owls | D247: CNTN | E247: C Stachera | F247: 3 | G247: 3 | H247: 0 | I247: 0 | J247: 0 | K247: 0 | L247: 0 | M247: 0 | N247: 0 | O247: 1 | P247: 0 | Q247: 0 | R247: B1 (plays #5-#7); entry inferred from play descriptions (Flag #1) — no Lineup changed note; opening pitcher for CNTN. K: J Cedeno K_S (play #6).
A248: 2026-03-14_CNTN_at_WSTM | B248: 46095 | C248: Westminster Varsity Owls | D248: CNTN | E248: A Lee | F248: 3 | G248: 5 | H248: 1 | I248: 1 | J248: 0 | K248: 0 | L248: 0 | M248: 1 | N248: 0 | O248: 2 | P248: 1 | Q248: 0 | R248: B2 (plays #11-#15); Lineup changed note play #11. H: B 1B (play #13). BB: B Barrett (play #12). K: C Messier K_S (play #14), W Shepperd K_L (play #15). R_Allowed=1: B Barrett scores on error by catcher B Harris embedded play #14 (CNTN Error #1) — run on error.
A249: 2026-03-14_CNTN_at_WSTM | B249: 46095 | C249: Westminster Varsity Owls | D249: CNTN | E249: C Proescher | F249: 3 | G249: 8 | H249: 2 | I249: 1 | J249: 1 | K249: 0 | L249: 0 | M249: 2 | N249: 0 | O249: 2 | P249: 3 | Q249: 1 | R249: B3 (plays #20-#27); Lineup changed note play #20. H: R Winebrunner 2B (play #20), B Barrett 1B (play #25). BB: M Stonesifer (play #24), B (play #26). K: C Stultz K_L (play #21), J Cedeno K_S (play #22). WP: play #27 embedded (M Stonesifer scores). R_Allowed=3: R Winebrunner scores on balk play #21 (balk not in schema, noted here — CNTN Error #2 same play embedded); Paul scores on B Barrett 1B play #25; M Stonesifer scores on WP play #27.
A250: 2026-03-14_CNTN_at_WSTM | B250: 46095 | C250: Westminster Varsity Owls | D250: CNTN | E250: A Barrett | F250: 3 | G250: 4 | H250: 0 | I250: 0 | J250: 0 | K250: 0 | L250: 0 | M250: 2 | N250: 0 | O250: 2 | P250: 1 | Q250: 1 | R250: B4 (plays #32-#35); Lineup changed note play #32. BB: W Shepperd (play #32), C Stultz (play #34). K: R Winebrunner K_L (play #33), J Cedeno K_S (play #35). WP: play #35 embedded (C Stultz scores). R_Allowed=1: C Stultz scores on WP embedded play #35. Runner Out: J Stone picked off at 3rd (out #2 in inning, embedded play #35 Sec4 — pitcher A Barrett to 3B A Lee). CNTN Error #4 by A Barrett embedded play #35.
A251: 2026-03-14_CNTN_at_WSTM | B251: 46095 | C251: Westminster Varsity Owls | D251: CNTN | E251: E Rayne | F251: 3 | G251: 4 | H251: 0 | I251: 0 | J251: 0 | K251: 0 | L251: 0 | M251: 1 | N251: 0 | O251: 1 | P251: 0 | Q251: 0 | R251: B5 (plays #39-#42); Lineup changed note play #39. BB: B Barrett (play #41). K: B K_L (play #42). R_Allowed=0.
A252: 2026-03-14_CNTN_at_WSTM | B252: 46095 | C252: Westminster Varsity Owls | D252: CNTN | E252: B Johnston | F252: 3 | G252: 4 | H252: 1 | I252: 1 | J252: 0 | K252: 0 | L252: 0 | M252: 0 | N252: 0 | O252: 2 | P252: 0 | Q252: 0 | R252: B6 (plays #47-#50); Lineup changed note play #47. H: C Messier 1B (play #47). K: W Shepperd K_L (play #48), C Stultz K_S (play #50). C Messier steals 2nd embedded play #50 Sec4 (during C Stultz K AB). R_Allowed=0.
A253: 2026-03-14_CNTN_at_WSTM | B253: 46095 | C253: Centennial Varsity Eagles | D253: WSTM | E253: B Barrett | F253: 9 | G253: 11 | H253: 1 | I253: 1 | J253: 0 | K253: 0 | L253: 0 | M253: 1 | N253: 0 | O253: 3 | P253: 0 | Q253: 0 | R253: T1-T3; Lineup changed note play #1. T1 BF=4 (A Gauthier K_S, E Rayne GO, C Bade 1B, A Banks PO), Outs=3, H=1, K=1. T2 BF=3 (B Harris GO, C Stachera PO, L Choe GO), Outs=3. T3 BF=4 (C Proescher K_L, B Johnston K_L, A Gauthier BB, E Rayne GO), Outs=3, K=2, BB=1. R_Allowed=0. B Barrett also bats for WSTM.
A254: 2026-03-14_CNTN_at_WSTM | B254: 46095 | C254: Centennial Varsity Eagles | D254: WSTM | E254: L Rohde | F254: 6 | G254: 7 | H254: 0 | I254: 0 | J254: 0 | K254: 0 | L254: 0 | M254: 1 | N254: 0 | O254: 1 | P254: 1 | Q254: 0 | R254: T4-T5; Lineup changed note play #28. T4 BF=4 (C Bade BB, A Banks PO, B Harris GO, C Stachera K_S), Outs=3, BB=1, K=1, R_Allowed=1 (C Bade scores on PB during C Stachera K AB play #31 — PB not in schema, noted here). T5 BF=3 (L Choe GO, C Proescher GO, B Johnston GO), Outs=3. R_Allowed=1 total.
A255: 2026-03-14_CNTN_at_WSTM | B255: 46095 | C255: Centennial Varsity Eagles | D255: WSTM | E255: W Shepperd | F255: 3 | G255: 4 | H255: 1 | I255: 1 | J255: 0 | K255: 0 | L255: 0 | M255: 0 | N255: 0 | O255: 2 | P255: 0 | Q255: 0 | R255: T6 (plays #43-#46); entry inferred from play descriptions (Flag #2) — no Lineup changed note. H: B Corrao 1B (play #43, mid-AB sub for A Gauthier — PA credited to B Corrao). K: A Barrett K_S (play #45), A Lee K_S (play #46). B Corrao steals 3rd embedded play #46 Sec4. R_Allowed=0. W Shepperd also bats for WSTM.
A256: 2026-03-14_CNTN_at_WSTM | B256: 46095 | C256: Centennial Varsity Eagles | D256: WSTM | E256: O Brilhart | F256: 3 | G256: 3 | H256: 0 | I256: 0 | J256: 0 | K256: 0 | L256: 0 | M256: 0 | N256: 0 | O256: 2 | P256: 0 | Q256: 0 | R256: T7 (plays #51-#53); Lineup changed note play #51. K: E Ogg K_S (play #51), W Sisolak K_L (play #53). LO: L Rivkin (play #52). R_Allowed=0.
A257: 2026-03-21_CNTN_at_WLDL | B257: 46102 | C257: Wilde Lake Varsity Cats | D257: CNTN | E257: C Stachera | F257: 12 | G257: 13 | H257: 0 | I257: 0 | J257: 0 | K257: 0 | L257: 0 | M257: 1 | N257: 0 | O257: 10 | P257: 0 | Q257: 0 | R257: B1-B4; entry play #7 (Lineup changed note). B1 BF=4 (T Sommer K_L, D Coleman BB, N Dalesio K_L, J Bunnell K_S foul tip), Outs=3, K=3, BB=1. B2 BF=3 (W Switzer K_S, R Schmidt GO, D Linares K_S), Outs=3, K=2. B3 BF=3 (B Habershon K_L, A Lindsay K_L, T Sommer GO), Outs=3, K=2; duplicate Lineup changed entry play #25 (Flag #4). B4 BF=3 (D Coleman K_L, N Dalesio K_S dropped 3rd, J Bunnell K_L), Outs=3, K=3. R_Allowed=0. PB B1 play #10 embedded (D Coleman 1st→2nd during J Bunnell foul-tip K AB) — PB not in schema, noted here. E Ogg PR for C Stachera T3 play #24 — C Stachera continues pitching (Flag #6). Also bats for CNTN.
A258: 2026-03-21_CNTN_at_WLDL | B258: 46102 | C258: Wilde Lake Varsity Cats | D258: CNTN | E258: E Rayne | F258: 3 | G258: 3 | H258: 0 | I258: 0 | J258: 0 | K258: 0 | L258: 0 | M258: 0 | N258: 0 | O258: 3 | P258: 0 | Q258: 0 | R258: B5; entry inferred from play descriptions (Flag #3) — no Lineup changed note. BF=3 (W Switzer K_S, R Schmidt K_S, D Linares K_S). 3 K, 0 BB, 0 H, R_Allowed=0. Also bats for CNTN.
... A283: 2026-03-31_CNTN_at_WLTR | B283: 46112 | C283: Walter Johnson Varsity Wildcats | D283: CNTN | E283: A Lee | F283: 12 | G283: 18 | H283: 3 | I283: 3 | J283: 0 | K283: 0 | L283: 0 | M283: 3 | N283: 0 | O283: 5 | P283: 1 | Q283: 1 | R283: B4-B7 (plays #38-42,#47-50,#55-58,#63-67). Entered play #38 — lineup change documented in B4. 1B×3 (H Bauer #38, J Gilder #40, J Pena Simon #63). BB×3 (S Weston #41, G Matalia IBB #64, L Rayment-Cruz IBB #65). K×5: C Martin K_S #39; G Matalia K_L #47; E Taylor K_S #50; S Gilcrest K_L #66; E Taylor K_S #67. WP play #41 (H Bauer advances 3rd, J Gilder advances 2nd during S Weston walk AB, B4). R_Allowed=1 (H Bauer scores on J Gilder SacFly play #57, B6). Outs include J Pena Simon CS home play #66 (out #1 of B7, embedded in S Gilcrest AB).

Sheet Fielding
A1: Game_ID | B1: Game_Date | C1: Opponent | D1: Team | E1: Player | F1: Inning | G1: Play_Ref | H1: Notes
A2: 2026-03-10_RVRH_at_WSTF | B2: 2026-03-10 | C2: Westfield High School | D2: RVRH | E2: E Skolkin | F2: 8 | G2: 69 | H2: #3 hits ground ball, reaches base on error by 2B E Skolkin (play #69, B8). RVRH E=1 per Section 2 totals. No errors recorded for WSTF.
A3: 2026-03-14_WTTN_at_RVRH | B3: 2026-03-14 | C3: Wootton Varsity Patriots | D3: RVRH | E3: H Zhang | F3: 5 | G3: 42 | H3: J Reid hits a hard ground ball and reaches on an error by 1B H Zhang (play #42, T5). RVRH E=1 per running tally.
A4: 2026-03-14_WTTN_at_RVRH | B4: 2026-03-14 | C4: Wootton Varsity Patriots | D4: RVRH | E4: B Bixby | F4: 6 | G4: 49 | H4: A Grainger hits a fly ball and reaches on an error by LF B Bixby (play #49, T6). RVRH E=2 per running tally.
A5: 2026-03-14_WTTN_at_RVRH | B5: 2026-03-14 | C5: Wootton Varsity Patriots | D5: RVRH | E5: B Bixby | F5: 6 | G5: 52 | H5: N Zweig hits a fly ball and reaches on an error by LF B Bixby; A Grainger scores on the play (play #52, T6). RVRH E=3 per running tally.
A6: 2026-03-14_WTTN_at_RVRH | B6: 2026-03-14 | C6: Wootton Varsity Patriots | D6: WTTN | E6: WTTN_1B | F6: 5 | G6: 45 | H6: C Reis advances to 2nd on error by WTTN first baseman; embedded in J Norwood pop out AB (play #45, B5; Flag #6). WTTN E=1 per running tally. Fielder identity not specified in log.
A7: 2026-03-14_WTTN_at_RVRH | B7: 2026-03-14 | C7: Wootton Varsity Patriots | D7: WTTN | E7: WTTN_SS | F7: 5 | G7: 46 | H7: H Zhang hits a ground ball and reaches on an error by WTTN shortstop (play #46, B5). WTTN E=2 per running tally. Fielder identity not specified in log.
A8: 2026-03-21_RVRH_at_GLFR | B8: 2026-03-21 | C8: Guilford Park Varsity Panthers | D8: GLFR | E8: GLFR_AA | F8: 1 | G8: 14 | H8: C Naecker hits a pop fly and reaches on an error by SS A A; C Naecker also advances to 2nd on same error (play #14, T1). GLFR E=1. Two separate advances credited to one error event; no RVRH error.
A9: 2026-03-21_RVRH_at_GLFR | B9: 2026-03-21 | C9: Guilford Park Varsity Panthers | D9: GLFR | E9: GLFR_AA | F9: 1 | G9: 15 | H9: G Dang hits a hard ground ball and reaches on an error by SS A A; C Naecker and H Zhang score on the play (play #15, T1). GLFR E=2. Runs scored on error — no RBI credited to G Dang.
A10: 2026-03-21_RVRH_at_GLFR | B10: 2026-03-21 | C10: Guilford Park Varsity Panthers | D10: GLFR | E10: GLFR_MR | F10: 2 | G10: 23 | H10: E McCoy advances to 2nd on an error by 1B M R during A Contreras AB (play #23, T2; embedded in Sec4 #23). GLFR E=3. Error embedded in pitch sequence, not a standalone play entry (Flag #11).
A11: 2026-03-23_WLDL_at_RVRH | B11: 2026-03-23 | C11: Wilde Lake Varsity Cats | D11: WLDL | E11: J Bunnell | F11: 2 | G11: 14 | H11: C Naecker scores on error by C (J Bunnell) during G Dang K AB (play #14, B2); error embedded in pitch sequence, not a standalone play entry (Flag #6). WLDL E=1.
A12: 2026-03-23_WLDL_at_RVRH | B12: 2026-03-23 | C12: Wilde Lake Varsity Cats | D12: WLDL | E12: R Schmidt | F12: 2 | G12: 16 | H12: A Fields advances to 2nd on error by 1B R Schmidt during E McCoy AB (play #16, B2); error embedded in pitch sequence (Sec4 #16). WLDL E=2.
A13: 2026-03-23_WLDL_at_RVRH | B13: 2026-03-23 | C13: Wilde Lake Varsity Cats | D13: WLDL | E13: A Lindsay | F13: 3 | G13: 24 | H13: J Norwood hits a fly ball and reaches on an error by RF A Lindsay; J Norwood advances to 2nd on the same error (play #24, B3). WLDL E=3.
... A22: 2026-03-30_FLLS_at_RVRH | B22: 2026-03-30 | C22: Fallston Varsity Cougars | D22: RVRH | E22: G Dang | F22: 5 | G22: 43 | H22: E Slicher scores on an error by C G Dang — embedded in F Rebasti walk AB pitch sequence (play #43, T5; Flag #3). RVRH E=2. Z Loewe steals 2nd on the same pitch. Error and SB both embedded; neither logged as standalone play entry.
A23: 2026-03-07_ELNR_at_NRTH | B23: 46088 | C23: North Point Varsity Eagles | D23: ELNR | E23: S Hamilton | F23: 1 | G23: 9 | H23: A Harding reaches on error by SS S Hamilton; A Espejo advances to 2nd (B1). ELNR E=1.
A24: 2026-03-07_ELNR_at_NRTH | B24: 46088 | C24: North Point Varsity Eagles | D24: ELNR | E24: J Maitland | F24: 1 | G24: 12 | H24: W Kwisnek singles; W Kwisnek advances to 3rd on error by C J Maitland; A Harding scores (B1). ELNR E=2. See Flag #4.
A25: 2026-03-07_ELNR_at_NRTH | B25: 46088 | C25: North Point Varsity Eagles | D25: ELNR | E25: J Maitland | F25: 1 | G25: 15 | H25: S Dixon scores on error by C J Maitland during C Pettko walk sequence (B1). ELNR E=3. See Flag #5.
A26: 2026-03-07_ELNR_at_NRTH | B26: 46088 | C26: North Point Varsity Eagles | D26: ELNR | E26: A Wimbish | F26: 2 | G26: 24 | H26: Z Bowman reaches and advances to 2nd on error by RF A Wimbish (B2). ELNR E=4.
A27: 2026-03-07_ELNR_at_NRTH | B27: 46088 | C27: North Point Varsity Eagles | D27: ELNR | E27: S Hamilton | F27: 2 | G27: 27 | H27: S Dixon reaches on error by SS S Hamilton; Z Bowman scores (B2). ELNR E=5.
A28: 2026-03-07_ELNR_at_NRTH | B28: 46088 | C28: North Point Varsity Eagles | D28: ELNR | E28: J Maitland | F28: 3 | G28: 36 | H28: T Roy scores on error by C J Maitland; C Pettko also advances — embedded in A Espejo walk sequence (B3). ELNR E=6. See Flag #5.
A29: 2026-03-07_ELNR_at_NRTH | B29: 46088 | C29: North Point Varsity Eagles | D29: ELNR | E29: R Coxen | F29: 3 | G29: 39 | H29: Z Bowman advances to 2nd on error by 2B R Coxen on throw during FC play (B3). ELNR E=7. See Flag #8.
A30: 2026-03-07_ELNR_at_NRTH | B30: 46088 | C30: North Point Varsity Eagles | D30: ELNR | E30: S Hamilton | F30: 5 | G30: 58 | H30: W Kwisnek reaches on error by SS S Hamilton (B5). ELNR E=8.
A31: 2026-03-07_ELNR_at_NRTH | B31: 46088 | C31: North Point Varsity Eagles | D31: NRTH | E31: Z Bowman | F31: 2 | G31: 19 | H31: A Kennell reaches on error by 3B Z Bowman (T2). NRTH E=1.
A32: 2026-03-07_ELNR_at_NRTH | B32: 46088 | C32: North Point Varsity Eagles | D32: NRTH | E32: Z Bowman | F32: 3 | G32: 32 | H32: K Watkins-Fleisher reaches; C Knight advances to 3rd on same error by 3B Z Bowman (T3). NRTH E=2.
A33: 2026-03-07_ELNR_at_NRTH | B33: 46088 | C33: North Point Varsity Eagles | D33: NRTH | E33: C Pettko | F33: 5 | G33: 53 | H33: J Maitland reaches on error by SS C Pettko (T5). NRTH E=3.
A34: 2026-03-14_NRTH_at_ARND | B34: 2026-03-14 | C34: ARND | D34: NRTH | E34: W Kwisnek | F34: 1 | G34: play#6 | H34: E at 1B; J Bailey reaches on error; see Flag#3
A35: 2026-03-14_NRTH_at_ARND | B35: 2026-03-14 | C35: ARND | D35: NRTH | E35: A Harding | F35: 1 | G35: play#8 | H35: E at SS; B Gardner reaches on error
A36: 2026-03-14_NRTH_at_ARND | B36: 2026-03-14 | C36: ARND | D36: NRTH | E36: A Williams | F36: 4 | G36: play#41 | H36: E at C; B Gardner scores on error; see Flag#5
A37: 2026-03-14_NRTH_at_ARND | B37: 2026-03-14 | C37: ARND | D37: NRTH | E37: A Harding | F37: 4 | G37: play#43 | H37: E at SS; J Bailey reaches on error; see Flag#6
A38: 2026-03-14_NRTH_at_ARND | B38: 2026-03-14 | C38: ARND | D38: NRTH | E38: A Harding | F38: 5 | G38: play#54 | H38: E at SS; J Verdier reaches on error
A39: 2026-03-14_NRTH_at_ARND | B39: 2026-03-14 | C39: ARND | D39: NRTH | E39: Z Bowman | F39: 5 | G39: play#58 | H39: E at 3B; J Niles reaches on error
A40: 2026-03-14_NRTH_at_ARND | B40: 2026-03-14 | C40: ARND | D40: NRTH | E40: A Thomas | F40: 5 | G40: play#62 | H40: E at 2B; J Verdier reaches on error
A41: 2026-03-14_NRTH_at_MRRT | B41: 2026-03-14 | C41: MRRT | D41: NRTH | E41: A Thomas | F41: 1 | G41: play#9 | H41: E at 2B embedded in A Devito AB; Z Magee advances to 2nd on E
A42: 2026-03-14_NRTH_at_MRRT | B42: 2026-03-14 | C42: MRRT | D42: NRTH | E42: A Williams | F42: 2 | G42: play#21 | H42: E at C embedded in N Brown AB; O Snow scores on E (steals 3rd then scores)
A43: 2026-03-14_NRTH_at_MRRT | B43: 2026-03-14 | C43: MRRT | D43: NRTH | E43: Z Bowman | F43: 3 | G43: play#30 | H43: E at 3B; J Devito reaches on error
A44: 2026-03-14_NRTH_at_MRRT | B44: 2026-03-14 | C44: MRRT | D44: NRTH | E44: Z Bowman | F44: 3 | G44: play#34 | H44: E at 3B; A Hlavaty reaches on error; J Devito scores on same error
A45: 2026-03-14_NRTH_at_MRRT | B45: 2026-03-14 | C45: MRRT | D45: NRTH | E45: S Dixon | F45: 5 | G45: play#51 | H45: E at LF embedded in #6 AB; A Montgomery (CR for T Rauscher) scores on E; see Flag#13
... A85: 2026-03-31_GLNL_at_ATHL | B85: 2026-03-31 | C85: GLNL | D85: ATHL | E85: J Whiting | F85: 5 | G85: play#38 | H85: E by SS J Whiting (ATHL); A Nazelrod (GLNL) reaches on ground ball, Top 5th; A Baker scores on this error (mid-AB J Bott entry); ATHL E=3 of 3
A86: 2026-03-07_HNTN_at_LNGR | B86: 46088 | C86: Long Reach HS | D86: HNTN | E86: J Cadden | F86: 2 | G86: 23 | H86: Pickoff attempt at 2nd — #15 advances to 3rd on error by SS J Cadden, #23 advances to 2nd on same error (play #23, Bot 2nd). HNTN E running tally: 1.
A87: 2026-03-07_HNTN_at_LNGR | B87: 46088 | C87: Huntingtown Varsity Hurricanes | D87: LNGR | E87: LNGR_#23 | F87: 4 | G87: 40 | H87: C Wargo hits a hard ground ball and reaches on an error by 1B LNGR_#23 (play #40, Top 4th). LNGR E=1.
...

Sheet Roster
A1: Team_Code | B1: Player | C1: First_Seen | D1: Notes
A2: ARND | B2: B Gardner | C2: 2026-03-14_NRTH_at_ARND
A3: ARND | B3: C Clarke | C3: 2026-03-14_NRTH_at_ARND
A4: ARND | B4: C Dennehy | C4: 2026-03-14_NRTH_at_ARND
A5: ARND | B5: C Wojtyszyn | C5: 2026-03-14_NRTH_at_ARND
A6: ARND | B6: F Doty | C6: 2026-03-14_NRTH_at_ARND
A7: ARND | B7: G O'Donnell | C7: 2026-03-14_NRTH_at_ARND | D7: Bats and pitches
A8: ARND | B8: G Pedrozo | C8: 2026-03-14_NRTH_at_ARND
A9: ARND | B9: J Bailey | C9: 2026-03-14_NRTH_at_ARND
A10: ARND | B10: J Fuller | C10: 2026-03-14_NRTH_at_ARND
A11: ARND | B11: J Haslup | C11: 2026-03-14_NRTH_at_ARND
A12: ARND | B12: J Niles | C12: 2026-03-14_NRTH_at_ARND
A13: ARND | B13: J Perry | C13: 2026-03-14_NRTH_at_ARND
A14: ARND | B14: J Verdier | C14: 2026-03-14_NRTH_at_ARND
A15: ARND | B15: J Witcher | C15: 2026-03-14_NRTH_at_ARND | D15: Bats and pitches
A16: ARND | B16: L Atherton | C16: 2026-03-14_NRTH_at_ARND | D16: Bats and pitches
A17: ARND | B17: L Gamble | C17: 2026-03-14_NRTH_at_ARND
A18: ARND | B18: P Smith | C18: 2026-03-14_NRTH_at_ARND
A19: ATHL | B19: A Chutka | C19: 2026-03-31_GLNL_at_ATHL
A20: ATHL | B20: B Skaggs | C20: 2026-03-31_GLNL_at_ATHL
A21: ATHL | B21: J Bott | C21: 2026-03-31_GLNL_at_ATHL | D21: Pitcher only (no batting rows in log)
A22: ATHL | B22: J Dailey | C22: 2026-03-31_GLNL_at_ATHL
A23: ATHL | B23: J Martin | C23: 2026-03-31_GLNL_at_ATHL
A24: ATHL | B24: J Whiting | C24: 2026-03-31_GLNL_at_ATHL
A25: ATHL | B25: L Byrns | C25: 2026-03-31_GLNL_at_ATHL | D25: Pitcher only (no batting rows in log)
A26: ATHL | B26: L Conroy | C26: 2026-03-31_GLNL_at_ATHL
A27: ATHL | B27: N Brewer | C27: 2026-03-31_GLNL_at_ATHL
A28: ATHL | B28: N Weinig | C28: 2026-03-31_GLNL_at_ATHL
A29: ATHL | B29: T MacKenzie | C29: 2026-03-31_GLNL_at_ATHL | D29: Bats and pitches
A30: ATHL | B30: W Martin | C30: 2026-03-31_GLNL_at_ATHL
A31: CHPT | B31: A Garner | C31: 2026-03-25_NRTH_at_CHPT
A32: CHPT | B32: A Norris | C32: 2026-03-25_NRTH_at_CHPT
A33: CHPT | B33: C Brickman | C33: 2026-03-25_NRTH_at_CHPT
A34: CHPT | B34: C Rabon | C34: 2026-03-25_NRTH_at_CHPT
A35: CHPT | B35: CHPT_#1 | C35: 2026-03-30_CHPT_at_HNTN
A36: CHPT | B36: CHPT_#10 | C36: 2026-03-30_CHPT_at_HNTN
A37: CHPT | B37: CHPT_#11 | C37: 2026-03-30_CHPT_at_HNTN | D37: Bats and pitches
A38: CHPT | B38: CHPT_#13 | C38: 2026-03-30_CHPT_at_HNTN | D38: Pitcher only (no batting rows in log)
A39: CHPT | B39: CHPT_#15 | C39: 2026-03-30_CHPT_at_HNTN | D39: Bats and pitches
A40: CHPT | B40: CHPT_#2 | C40: 2026-03-30_CHPT_at_HNTN
...

Sheet Derivation_Rules
A1: RIVERHILL HAWKS — SCOUTING REPOSITORY: DERIVATION RULES
A3: Rule | B3: Definition | C3: Source / Notes
A4: AB | B4: PA − BB − HBP − SAC | C4: Reached-on-error and FC count as AB. Dropped 3rd strike counts as AB + K.
A5: H | B5: 1B + 2B + 3B + HR | C5: Reached-on-error does NOT count as H (counted as AB only).
A6: R (batter) | B6: Runs scored by that player | C6: COURTESY RUNNER RULE: run credited to original player, not the CR. E.g. T1 play #3: B Bixby (CR for R Walsh) scores → R Walsh R+1, B Bixby R unchanged.
A7: RBI | B7: Runs that score as a direct result of the batter's PA | C7: Productive out RBI counted (e.g. C Naecker T1 GO, J Norwood scores = 1 RBI).
A8: SB / CS | B8: Stolen bases and caught stealing per player | C8: Often embedded within pitch sequences (Section 4) rather than logged as discrete plays. Extract from mid-AB notations in Section 4.
A9: Outs_Recorded (pitcher) | B9: Count of outs attributed to pitcher's tenure | C9: Derive from Section 3 'Outs (End of Play)' column during pitcher's active innings. DO NOT use inning count. Handles partial innings cleanly. IP = Outs_Recorded/3 via formula.
A10: R_Allowed (pitcher) | B10: Runs that score while the pitcher is on the mound | C10: Charged to the pitcher active when the run scores, regardless of who put the runner on base.
A11: WP | B11: Wild pitches — embedded in Section 4 pitch sequences | C11: E.g. play #40 pitch seq includes '#6 advances to 3rd on wild pitch' → J Jenkins WP+1.
A12: PB | B12: Passed ball — embedded in Section 4 pitch sequences | C12: E.g. play #61 pitch seq: 'R Miller advances to 2nd on passed ball'. NOT currently tracked in Pitching schema — note in pitcher Notes column.
A13: Player key (opponent) | B13: Format: [OPP_CODE]_#[NUMBER] — no spaces | C13: Example: WSTF_#4. Consistent format required for SUMIF/COUNTIF across games.
A14: SAC | B14: Sacrifice bunt or fly — default 0 unless Outcome field explicitly states 'sacrifice' | C14: Productive groundouts are NOT sacrifices. This game: SAC = 0 for all players (no explicit sacrifice coded in log).
... A17: QA_Flag_Count | B17: Count of checked [x] flags in Section 5 of source markdown | C17: Game_01.md has 10 active flags. Review Notes columns for flag references.
A19: FORMULAS TO BUILD IN EXCEL (examples)
A20: AVG | B20: =H/AB | C20: Batting average
A21: OBP | B21: =(H+BB+HBP)/(AB+BB+HBP+SAC) | C21: On-base percentage
A22: SLG | B22: =(1B + 2*2B + 3*3B + 4*HR)/AB | C22: Slugging percentage
A23: OPS | B23: =OBP+SLG | C23: On-base plus slugging
A24: TB | B24: =1B + 2*2B + 3*3B + 4*HR | C24: Total bases
A25: IP | B25: =Outs_Recorded/3 | C25: Innings pitched
A26: WHIP | B26: =(BB_Allowed+H_Allowed)/IP | C26: Walks + hits per inning pitched
A27: K/BB | B27: =K/BB_Allowed | C27: Strikeout-to-walk ratio
A28: BB% | B28: =BB/PA | C28: Walk rate (batter)
A29: K% | B29: =K/PA | C29: Strikeout rate (batter)

Sheet Playoff_Threat_Matrix
A1: CLASS 2A PLAYOFF THREAT ASSESSMENT
A2: Auto-updates as new games are added to Game_Log
A4: Team | B4: Games_Played | C4: Est_Record | D4: Runs_Per_Game | E4: Team_AVG | F4: Team_ERA | G4: Errors_Per_Game | H4: Threat_Score | I4: Threat_Level
A5: HNTN | B5: =COUNTIF(Game_Log!$D$2:$D$5000,A5) | C5: See Game_Log | D5: =IFERROR(SUMIFS(Batting!$M$2:$M$5000,Batting!$D$2:$D$5000,A5)/B5,"Insufficient Data") | E5: =IFERROR(SUMIFS(Batting!$H$2:$H$5000,Batting!$D$2:$D$5000,A5)/SUMIFS(Batting!$G$2:$G$5000,Batting!$D$2:$D$5000,A5),"Insufficient Data") | F5: =IFERROR((SUMIFS(Pitching!$Q$2:$Q$5000,Pitching!$D$2:$D$5000,A5)*7)/(SUMIFS(Pitching!$F$2:$F$5000,Pitching!$D$2:$D$5000,A5)/3),"Insufficient Data") | G5: =IFERROR(COUNTIFS(Fielding!$D$2:$D$5000,A5)/B5,"Insufficient Data") | H5: =IFERROR((D5/1.5)*0.4+(10-(F5/1.5))*0.4+(10-G5*2)*0.2,0) | I5: =IF(H5>=7.5,"EXTREME",IF(H5>=6,"HIGH",IF(H5>=4,"MEDIUM","LOW")))
A6: NRTH | B6: =COUNTIF(Game_Log!$D$2:$D$5000,A6) | C6: See Game_Log | D6: =IFERROR(SUMIFS(Batting!$M$2:$M$5000,Batting!$D$2:$D$5000,A6)/B6,"Insufficient Data") | E6: =IFERROR(SUMIFS(Batting!$H$2:$H$5000,Batting!$D$2:$D$5000,A6)/SUMIFS(Batting!$G$2:$G$5000,Batting!$D$2:$D$5000,A6),"Insufficient Data") | F6: =IFERROR((SUMIFS(Pitching!$Q$2:$Q$5000,Pitching!$D$2:$D$5000,A6)*7)/(SUMIFS(Pitching!$F$2:$F$5000,Pitching!$D$2:$D$5000,A6)/3),"Insufficient Data") | G6: =IFERROR(COUNTIFS(Fielding!$D$2:$D$5000,A6)/B6,"Insufficient Data") | H6: =IFERROR((D6/1.5)*0.4+(10-(F6/1.5))*0.4+(10-G6*2)*0.2,0) | I6: =IF(H6>=7.5,"EXTREME",IF(H6>=6,"HIGH",IF(H6>=4,"MEDIUM","LOW")))
A7: GLNL | B7: =COUNTIF(Game_Log!$D$2:$D$5000,A7) | C7: See Game_Log | D7: =IFERROR(SUMIFS(Batting!$M$2:$M$5000,Batting!$D$2:$D$5000,A7)/B7,"Insufficient Data") | E7: =IFERROR(SUMIFS(Batting!$H$2:$H$5000,Batting!$D$2:$D$5000,A7)/SUMIFS(Batting!$G$2:$G$5000,Batting!$D$2:$D$5000,A7),"Insufficient Data") | F7: =IFERROR((SUMIFS(Pitching!$Q$2:$Q$5000,Pitching!$D$2:$D$5000,A7)*7)/(SUMIFS(Pitching!$F$2:$F$5000,Pitching!$D$2:$D$5000,A7)/3),"Insufficient Data") | G7: =IFERROR(COUNTIFS(Fielding!$D$2:$D$5000,A7)/B7,"Insufficient Data") | H7: =IFERROR((D7/1.5)*0.4+(10-(F7/1.5))*0.4+(10-G7*2)*0.2,0) | I7: =IF(H7>=7.5,"EXTREME",IF(H7>=6,"HIGH",IF(H7>=4,"MEDIUM","LOW")))
A8: CNTN | B8: =COUNTIF(Game_Log!$D$2:$D$5000,A8) | C8: See Game_Log | D8: =IFERROR(SUMIFS(Batting!$M$2:$M$5000,Batting!$D$2:$D$5000,A8)/B8,"Insufficient Data") | E8: =IFERROR(SUMIFS(Batting!$H$2:$H$5000,Batting!$D$2:$D$5000,A8)/SUMIFS(Batting!$G$2:$G$5000,Batting!$D$2:$D$5000,A8),"Insufficient Data") | F8: =IFERROR((SUMIFS(Pitching!$Q$2:$Q$5000,Pitching!$D$2:$D$5000,A8)*7)/(SUMIFS(Pitching!$F$2:$F$5000,Pitching!$D$2:$D$5000,A8)/3),"Insufficient Data") | G8: =IFERROR(COUNTIFS(Fielding!$D$2:$D$5000,A8)/B8,"Insufficient Data") | H8: =IFERROR((D8/1.5)*0.4+(10-(F8/1.5))*0.4+(10-G8*2)*0.2,0) | I8: =IF(H8>=7.5,"EXTREME",IF(H8>=6,"HIGH",IF(H8>=4,"MEDIUM","LOW")))
A9: PLYV | B9: =COUNTIF(Game_Log!$D$2:$D$5000,A9) | C9: See Game_Log | D9: =IFERROR(SUMIFS(Batting!$M$2:$M$5000,Batting!$D$2:$D$5000,A9)/B9,"Insufficient Data") | E9: =IFERROR(SUMIFS(Batting!$H$2:$H$5000,Batting!$D$2:$D$5000,A9)/SUMIFS(Batting!$G$2:$G$5000,Batting!$D$2:$D$5000,A9),"Insufficient Data") | F9: =IFERROR((SUMIFS(Pitching!$Q$2:$Q$5000,Pitching!$D$2:$D$5000,A9)*7)/(SUMIFS(Pitching!$F$2:$F$5000,Pitching!$D$2:$D$5000,A9)/3),"Insufficient Data") | G9: =IFERROR(COUNTIFS(Fielding!$D$2:$D$5000,A9)/B9,"Insufficient Data") | H9: =IFERROR((D9/1.5)*0.4+(10-(F9/1.5))*0.4+(10-G9*2)*0.2,0) | I9: =IF(H9>=7.5,"EXTREME",IF(H9>=6,"HIGH",IF(H9>=4,"MEDIUM","LOW")))
A10: HWRD | B10: =COUNTIF(Game_Log!$D$2:$D$5000,A10) | C10: See Game_Log | D10: =IFERROR(SUMIFS(Batting!$M$2:$M$5000,Batting!$D$2:$D$5000,A10)/B10,"Insufficient Data") | E10: =IFERROR(SUMIFS(Batting!$H$2:$H$5000,Batting!$D$2:$D$5000,A10)/SUMIFS(Batting!$G$2:$G$5000,Batting!$D$2:$D$5000,A10),"Insufficient Data") | F10: =IFERROR((SUMIFS(Pitching!$Q$2:$Q$5000,Pitching!$D$2:$D$5000,A10)*7)/(SUMIFS(Pitching!$F$2:$F$5000,Pitching!$D$2:$D$5000,A10)/3),"Insufficient Data") | G10: =IFERROR(COUNTIFS(Fielding!$D$2:$D$5000,A10)/B10,"Insufficient Data") | H10: =IFERROR((D10/1.5)*0.4+(10-(F10/1.5))*0.4+(10-G10*2)*0.2,0) | I10: =IF(H10>=7.5,"EXTREME",IF(H10>=6,"HIGH",IF(H10>=4,"MEDIUM","LOW")))

Sheet Opponent_Rotations
A1: OPPONENT PITCHING ROTATIONS
A2: Tracks starting pitchers and predicts next start based on rest patterns
A4: Team | B4: Pitcher | C4: Total_Starts | D4: Avg_IP_Per_Start | E4: ERA | F4: Total_BF | G4: Strikeouts | H4: Last_Start_Date | I4: Rotation_Notes
A5: Use Pitching sheet to track opponent starters

Sheet Hitter_Threat_Assessment
A1: HITTER THREAT ASSESSMENT - Most Dangerous Batters
A2: Scouts: Focus on HIGH THREAT or above when game planning
A4: Player | B4: Team | C4: PA | D4: OBP | E4: SLG | F4: RBI_Per_Hit | G4: K_Rate | H4: XBH | I4: Threat_Score | J4: Threat_Tier | K4: Scouting_Notes | L4: Lineup_Slot
A5: FORMULA: Threat_Score = (OBP×40%) + (SLG×30%) + (RBI/H×15%) + (Contact×15%)
